<robot name="robot">
  <link name="base_link">
    <visual>
      <origin xyz="0 0 0.1291011279735872" rpy="0 0 0" />
      <geometry>
        <box size="0.3 0.3 0.15" />
      </geometry>
      <material name="base_link-material">
        <color rgba="0.006048833020386069 0.9473065367320066 0.0069954101845983935 1" />
      </material>
    </visual>
    <collision>
      <origin xyz="0 0 0.1291011279735872" rpy="0 0 0" />
      <geometry>
        <box size="0.3 0.3 0.15" />
      </geometry>
    </collision>
    <inertial>
      <origin xyz="0 0 0.1291011279735872" rpy="0 0 0" />
      <mass value="1" />
      <inertia ixx="0.16666666666666666" ixy="0" ixz="0" iyy="0.16666666666666666" iyz="0" izz="0.16666666666666666" />
    </inertial>
  </link>
  <link name="cylinder1">
    <visual>
      <origin xyz="0 0 0" rpy="0 0 0" />
      <geometry>
        <cylinder radius="0.05" length="0.1" />
      </geometry>
      <material name="cylinder1-material">
        <color rgba="0.10461648408208657 0.015996293361446288 0.514917665367466 1" />
      </material>
    </visual>
    <collision>
      <origin xyz="0 0 0" rpy="0 0 0" />
      <geometry>
        <cylinder radius="0.05" length="0.1" />
      </geometry>
    </collision>
    <inertial>
      <origin xyz="0 0 0" rpy="0 0 0" />
      <mass value="1" />
      <inertia ixx="0.3333333333333333" ixy="0" ixz="0" iyy="0.5" iyz="0" izz="0.3333333333333333" />
    </inertial>
  </link>
  <joint name="base_link_to_cylinder1" type="fixed">
    <parent link="base_link" />
    <child link="cylinder1" />
    <origin xyz="0 0 0.05122113929521599" rpy="1.5707963267948966 2.220446049250313e-16 1.5707963267948963" />
  </joint>
  <link name="cube3">
    <visual>
      <origin xyz="0 0 0" rpy="0 0 0" />
      <geometry>
        <box size="0.1 0.1 0.1" />
      </geometry>
      <material name="cube3-material">
        <color rgba="0.08865558627723595 0.13563332964548108 0.5647115056965487 1" />
      </material>
    </visual>
    <collision>
      <origin xyz="0 0 0" rpy="0 0 0" />
      <geometry>
        <box size="0.1 0.1 0.1" />
      </geometry>
    </collision>
    <inertial>
      <origin xyz="0 0 0" rpy="0 0 0" />
      <mass value="1" />
      <inertia ixx="0.16666666666666666" ixy="0" ixz="0" iyy="0.16666666666666666" iyz="0" izz="0.16666666666666666" />
    </inertial>
  </link>
  <joint name="base_link_to_cube3" type="revolute">
    <parent link="base_link" />
    <child link="cube3" />
    <origin xyz="0.09490880780581268 0.09748329533451194 0.25430133179925585" rpy="0 0 0" />
    <axis xyz="0 0 1"/>
    <limit effort="1000.0" lower="-1" upper="1" velocity="0.5"/>  </joint>
  <link name="cube3-copy3">
    <visual>
      <origin xyz="0 0 0" rpy="0 0 0" />
      <geometry>
        <box size="0.1 0.1 0.1" />
      </geometry>
      <material name="cube3-copy3-material">
        <color rgba="0.08865558627723595 0.13563332964548108 0.5647115056965487 1" />
      </material>
    </visual>
    <collision>
      <origin xyz="0 0 0" rpy="0 0 0" />
      <geometry>
        <box size="0.1 0.1 0.1" />
      </geometry>
    </collision>
    <inertial>
      <origin xyz="0 0 0" rpy="0 0 0" />
      <mass value="1" />
      <inertia ixx="0.16666666666666666" ixy="0" ixz="0" iyy="0.16666666666666666" iyz="0" izz="0.16666666666666666" />
    </inertial>
  </link>
  <joint name="cube3_to_cube3-copy3" type="revolute">
    <parent link="cube3" />
    <child link="cube3-copy3" />
    <origin xyz="0.0977326868794024 0 0" rpy="0 1.5707963267948966 0" />
    <axis xyz="0 0 1"/>
    <limit effort="1000.0" lower="-1" upper="1" velocity="0.5"/>  </joint>
  <link name="cylinder3-copy5">
    <visual>
      <origin xyz="2.7755575615628914e-17 -3.903127820947816e-17 -1.3877787807814457e-17" rpy="0 0 0" />
      <geometry>
        <cylinder radius="0.045" length="0.25" />
      </geometry>
      <material name="cylinder3-copy5-material">
        <color rgba="0.6583748172725346 0.036889450395083165 0.012983032338510335 1" />
      </material>
    </visual>
    <collision>
      <origin xyz="2.7755575615628914e-17 -3.903127820947816e-17 -1.3877787807814457e-17" rpy="0 0 0" />
      <geometry>
        <cylinder radius="0.045" length="0.25" />
      </geometry>
    </collision>
    <inertial>
      <origin xyz="2.7755575615628914e-17 -3.903127820947816e-17 -1.3877787807814457e-17" rpy="0 0 0" />
      <mass value="1" />
      <inertia ixx="0.3333333333333333" ixy="0" ixz="0" iyy="0.5" iyz="0" izz="0.3333333333333333" />
    </inertial>
  </link>
  <joint name="cube3-copy3_to_cylinder3-copy5" type="fixed">
    <parent link="cube3-copy3" />
    <child link="cylinder3-copy5" />
    <origin xyz="-0.009420597854085 0.17490331386129884 0.004821036014162006" rpy="-2.356194490192345 1.5707963267948966 -0.7853981633974483" />
  </joint>
  <link name="cylinder3">
    <visual>
      <origin xyz="2.7755575615628914e-17 -3.903127820947816e-17 -1.3877787807814457e-17" rpy="0 0 0" />
      <geometry>
        <cylinder radius="0.04" length="0.25" />
      </geometry>
      <material name="cylinder3-material">
        <color rgba="0.6583748172725346 0.036889450395083165 0.012983032338510335 1" />
      </material>
    </visual>
    <collision>
      <origin xyz="2.7755575615628914e-17 -3.903127820947816e-17 -1.3877787807814457e-17" rpy="0 0 0" />
      <geometry>
        <cylinder radius="0.04" length="0.25" />
      </geometry>
    </collision>
    <inertial>
      <origin xyz="2.7755575615628914e-17 -3.903127820947816e-17 -1.3877787807814457e-17" rpy="0 0 0" />
      <mass value="1" />
      <inertia ixx="0.3333333333333333" ixy="0" ixz="0" iyy="0.5" iyz="0" izz="0.3333333333333333" />
    </inertial>
  </link>
  <joint name="cylinder3-copy5_to_cylinder3" type="prismatic">
    <parent link="cylinder3-copy5" />
    <child link="cylinder3" />
    <origin xyz="2.7028641463453882e-17 -4.336808689942018e-19 0.0032738203768583746" rpy="0 0 0" />
    <axis xyz="0 0 1"/>
    <limit effort="1000.0" lower="0" upper="1" velocity="0.5"/>  </joint>
  <link name="cylinder3-copy0">
    <visual>
      <origin xyz="0 0 0" rpy="0 0 0" />
      <geometry>
        <cylinder radius="0.035" length="0.25" />
      </geometry>
      <material name="cylinder3-copy0-material">
        <color rgba="0.6583748172725346 0.036889450395083165 0.012983032338510335 1" />
      </material>
    </visual>
    <collision>
      <origin xyz="0 0 0" rpy="0 0 0" />
      <geometry>
        <cylinder radius="0.035" length="0.25" />
      </geometry>
    </collision>
    <inertial>
      <origin xyz="0 0 0" rpy="0 0 0" />
      <mass value="1" />
      <inertia ixx="0.3333333333333333" ixy="0" ixz="0" iyy="0.5" iyz="0" izz="0.3333333333333333" />
    </inertial>
  </link>
  <joint name="cylinder3_to_cylinder3-copy0" type="prismatic">
    <parent link="cylinder3" />
    <child link="cylinder3-copy0" />
    <origin xyz="5.388818844109483e-17 -6.808789643208968e-17 0.004016047725078617" rpy="0 0 0" />
    <axis xyz="0 0 1"/>
    <limit effort="1000.0" lower="0" upper="0.2" velocity="0.5"/>  </joint>
  <link name="cylinder3-copy1">
    <visual>
      <origin xyz="0 0 0" rpy="0 0 0" />
      <geometry>
        <cylinder radius="0.03" length="0.25" />
      </geometry>
      <material name="cylinder3-copy1-material">
        <color rgba="0.6583748172725346 0.036889450395083165 0.012983032338510335 1" />
      </material>
    </visual>
    <collision>
      <origin xyz="0 0 0" rpy="0 0 0" />
      <geometry>
        <cylinder radius="0.03" length="0.25" />
      </geometry>
    </collision>
    <inertial>
      <origin xyz="0 0 0" rpy="0 0 0" />
      <mass value="1" />
      <inertia ixx="0.3333333333333333" ixy="0" ixz="0" iyy="0.5" iyz="0" izz="0.3333333333333333" />
    </inertial>
  </link>
  <joint name="cylinder3-copy0_to_cylinder3-copy1" type="prismatic">
    <parent link="cylinder3-copy0" />
    <child link="cylinder3-copy1" />
    <origin xyz="-9.301005920151903e-19 -1.235990476633475e-17 0.003018064157115752" rpy="0 0 0" />
    <axis xyz="0 0 1"/>
    <limit effort="1000.0" lower="0" upper="0.2" velocity="0.5"/>  </joint>
  <link name="cube3-copy2">
    <visual>
      <origin xyz="0 0 0" rpy="0 0 0" />
      <geometry>
        <box size="0.03 0.03 0.1" />
      </geometry>
      <material name="cube3-copy2-material">
        <color rgba="0.08865558627723595 0.13563332964548108 0.5647115056965487 1" />
      </material>
    </visual>
    <collision>
      <origin xyz="0 0 0" rpy="0 0 0" />
      <geometry>
        <box size="0.03 0.03 0.1" />
      </geometry>
    </collision>
    <inertial>
      <origin xyz="0 0 0" rpy="0 0 0" />
      <mass value="1" />
      <inertia ixx="0.16666666666666666" ixy="0" ixz="0" iyy="0.16666666666666666" iyz="0" izz="0.16666666666666666" />
    </inertial>
  </link>
  <joint name="cylinder3-copy1_to_cube3-copy2" type="fixed">
    <parent link="cylinder3-copy1" />
    <child link="cube3-copy2" />
    <origin xyz="-0.0031223829591222113 -0.028689304082221243 0.13915032059303187" rpy="-1.5707963267948963 0 0" />
  </joint>
  <link name="cube3-copy0">
    <visual>
      <origin xyz="0 0 0" rpy="0 0 0" />
      <geometry>
        <box size="0.1 0.1 0.1" />
      </geometry>
      <material name="cube3-copy0-material">
        <color rgba="0.08865558627723595 0.13563332964548108 0.5647115056965487 1" />
      </material>
    </visual>
    <collision>
      <origin xyz="0 0 0" rpy="0 0 0" />
      <geometry>
        <box size="0.1 0.1 0.1" />
      </geometry>
    </collision>
    <inertial>
      <origin xyz="0 0 0" rpy="0 0 0" />
      <mass value="1" />
      <inertia ixx="0.16666666666666666" ixy="0" ixz="0" iyy="0.16666666666666666" iyz="0" izz="0.16666666666666666" />
    </inertial>
  </link>
  <joint name="base_link_to_cube3-copy0" type="revolute">
    <parent link="base_link" />
    <child link="cube3-copy0" />
    <origin xyz="-0.09726916492783255 0.09748329533451194 0.25430133179925585" rpy="0 0 0" />
    <axis xyz="0 0 1"/>
    <limit effort="1000.0" lower="-1" upper="1" velocity="0.5"/>  </joint>
  <link name="cube3-copy4">
    <visual>
      <origin xyz="0 0 0" rpy="0 0 0" />
      <geometry>
        <box size="0.1 0.1 0.1" />
      </geometry>
      <material name="cube3-copy4-material">
        <color rgba="0.08865558627723595 0.13563332964548108 0.5647115056965487 1" />
      </material>
    </visual>
    <collision>
      <origin xyz="0 0 0" rpy="0 0 0" />
      <geometry>
        <box size="0.1 0.1 0.1" />
      </geometry>
    </collision>
    <inertial>
      <origin xyz="0 0 0" rpy="0 0 0" />
      <mass value="1" />
      <inertia ixx="0.16666666666666666" ixy="0" ixz="0" iyy="0.16666666666666666" iyz="0" izz="0.16666666666666666" />
    </inertial>
  </link>
  <joint name="cube3-copy0_to_cube3-copy4" type="revolute">
    <parent link="cube3-copy0" />
    <child link="cube3-copy4" />
    <origin xyz="-0.09985074079374005 0 0" rpy="0 1.5707963267948966 0" />
    <axis xyz="0 0 1"/>
    <limit effort="1000.0" lower="-1" upper="1" velocity="0.5"/>  </joint>
  <link name="cylinder3-copy6">
    <visual>
      <origin xyz="2.7755575615628914e-17 -3.903127820947816e-17 -1.3877787807814457e-17" rpy="0 0 0" />
      <geometry>
        <cylinder radius="0.045" length="0.25" />
      </geometry>
      <material name="cylinder3-copy6-material">
        <color rgba="0.6583748172725346 0.036889450395083165 0.012983032338510335 1" />
      </material>
    </visual>
    <collision>
      <origin xyz="2.7755575615628914e-17 -3.903127820947816e-17 -1.3877787807814457e-17" rpy="0 0 0" />
      <geometry>
        <cylinder radius="0.045" length="0.25" />
      </geometry>
    </collision>
    <inertial>
      <origin xyz="2.7755575615628914e-17 -3.903127820947816e-17 -1.3877787807814457e-17" rpy="0 0 0" />
      <mass value="1" />
      <inertia ixx="0.3333333333333333" ixy="0" ixz="0" iyy="0.5" iyz="0" izz="0.3333333333333333" />
    </inertial>
  </link>
  <joint name="cube3-copy4_to_cylinder3-copy6" type="fixed">
    <parent link="cube3-copy4" />
    <child link="cylinder3-copy6" />
    <origin xyz="-0.009420597854085 0.17490331386129884 0.004821036014162006" rpy="-2.356194490192345 1.5707963267948966 -0.7853981633974483" />
  </joint>
  <link name="cylinder3-copy2">
    <visual>
      <origin xyz="2.7755575615628914e-17 -3.903127820947816e-17 -1.3877787807814457e-17" rpy="0 0 0" />
      <geometry>
        <cylinder radius="0.04" length="0.25" />
      </geometry>
      <material name="cylinder3-copy2-material">
        <color rgba="0.6583748172725346 0.036889450395083165 0.012983032338510335 1" />
      </material>
    </visual>
    <collision>
      <origin xyz="2.7755575615628914e-17 -3.903127820947816e-17 -1.3877787807814457e-17" rpy="0 0 0" />
      <geometry>
        <cylinder radius="0.04" length="0.25" />
      </geometry>
    </collision>
    <inertial>
      <origin xyz="2.7755575615628914e-17 -3.903127820947816e-17 -1.3877787807814457e-17" rpy="0 0 0" />
      <mass value="1" />
      <inertia ixx="0.3333333333333333" ixy="0" ixz="0" iyy="0.5" iyz="0" izz="0.3333333333333333" />
    </inertial>
  </link>
  <joint name="cylinder3-copy6_to_cylinder3-copy2" type="prismatic">
    <parent link="cylinder3-copy6" />
    <child link="cylinder3-copy2" />
    <origin xyz="2.7028641463453882e-17 -4.336808689942018e-19 0.0032738203768583746" rpy="0 0 0" />
    <axis xyz="0 0 1"/>
    <limit effort="1000.0" lower="0" upper="1" velocity="0.5"/>  </joint>
  <link name="cylinder3-copy3">
    <visual>
      <origin xyz="0 0 0" rpy="0 0 0" />
      <geometry>
        <cylinder radius="0.035" length="0.25" />
      </geometry>
      <material name="cylinder3-copy3-material">
        <color rgba="0.6583748172725346 0.036889450395083165 0.012983032338510335 1" />
      </material>
    </visual>
    <collision>
      <origin xyz="0 0 0" rpy="0 0 0" />
      <geometry>
        <cylinder radius="0.035" length="0.25" />
      </geometry>
    </collision>
    <inertial>
      <origin xyz="0 0 0" rpy="0 0 0" />
      <mass value="1" />
      <inertia ixx="0.3333333333333333" ixy="0" ixz="0" iyy="0.5" iyz="0" izz="0.3333333333333333" />
    </inertial>
  </link>
  <joint name="cylinder3-copy2_to_cylinder3-copy3" type="prismatic">
    <parent link="cylinder3-copy2" />
    <child link="cylinder3-copy3" />
    <origin xyz="5.388818844109483e-17 -6.808789643208968e-17 0.004016047725078617" rpy="0 0 0" />
    <axis xyz="0 0 1"/>
    <limit effort="1000.0" lower="0" upper="0.2" velocity="0.5"/>  </joint>
  <link name="cylinder3-copy4">
    <visual>
      <origin xyz="0 0 0" rpy="0 0 0" />
      <geometry>
        <cylinder radius="0.03" length="0.25" />
      </geometry>
      <material name="cylinder3-copy4-material">
        <color rgba="0.6583748172725346 0.036889450395083165 0.012983032338510335 1" />
      </material>
    </visual>
    <collision>
      <origin xyz="0 0 0" rpy="0 0 0" />
      <geometry>
        <cylinder radius="0.03" length="0.25" />
      </geometry>
    </collision>
    <inertial>
      <origin xyz="0 0 0" rpy="0 0 0" />
      <mass value="1" />
      <inertia ixx="0.3333333333333333" ixy="0" ixz="0" iyy="0.5" iyz="0" izz="0.3333333333333333" />
    </inertial>
  </link>
  <joint name="cylinder3-copy3_to_cylinder3-copy4" type="prismatic">
    <parent link="cylinder3-copy3" />
    <child link="cylinder3-copy4" />
    <origin xyz="-9.301005920151903e-19 -1.235990476633475e-17 0.003018064157115752" rpy="0 0 0" />
    <axis xyz="0 0 1"/>
    <limit effort="1000.0" lower="0" upper="0.2" velocity="0.5"/>  </joint>
  <link name="cube3-copy5">
    <visual>
      <origin xyz="0 0 0" rpy="0 0 0" />
      <geometry>
        <box size="0.03 0.03 0.1" />
      </geometry>
      <material name="cube3-copy5-material">
        <color rgba="0.08865558627723595 0.13563332964548108 0.5647115056965487 1" />
      </material>
    </visual>
    <collision>
      <origin xyz="0 0 0" rpy="0 0 0" />
      <geometry>
        <box size="0.03 0.03 0.1" />
      </geometry>
    </collision>
    <inertial>
      <origin xyz="0 0 0" rpy="0 0 0" />
      <mass value="1" />
      <inertia ixx="0.16666666666666666" ixy="0" ixz="0" iyy="0.16666666666666666" iyz="0" izz="0.16666666666666666" />
    </inertial>
  </link>
  <joint name="cylinder3-copy4_to_cube3-copy5" type="fixed">
    <parent link="cylinder3-copy4" />
    <child link="cube3-copy5" />
    <origin xyz="-0.0031223829591222113 -0.028689304082221243 0.13915032059303187" rpy="-1.5707963267948963 0 0" />
  </joint>
</robot>